<?xml version="1.0" ?>
<!-- =================================================================================== -->
<!-- |    This document was autogenerated by xacro from lr1_basic.xacro                | -->
<!-- |    EDITING THIS FILE BY HAND IS NOT RECOMMENDED                                 | -->
<!-- =================================================================================== -->
<robot name="lr1_robot" xmlns:xacro="http://ros.org/wiki/xacro">
  <!-- Include all component files -->
  <link name="support_link">
    <visual>
      <geometry>
        <mesh filename="package://lr1_description/meshes/support.STL"/>
      </geometry>
      <material name="white">
        <color rgba="1 1 1 1"/>
      </material>
    </visual>
    <collision>
      <origin rpy="0 0 0" xyz="0 0 -0.04"/>
      <geometry>
        <box size="0.45 0.45 0.08"/>
      </geometry>
    </collision>
  </link>
  <joint name="support_waist_joint" type="continuous">
    <axis xyz="0 0 1"/>
    <origin rpy="0 0 0" xyz="0 0 0.0165"/>
    <parent link="support_link"/>
    <child link="waist_link"/>
  </joint>
  <link name="waist_link">
    <visual>
      <geometry>
        <mesh filename="package://lr1_description/meshes/waist.STL"/>
      </geometry>
      <origin rpy="0 0 0" xyz="0 0 0"/>
      <material name="lyellow">
        <color rgba="0.33 0 0 1"/>
      </material>
    </visual>
    <collision>
      <origin rpy="0 0 0" xyz="0 0 0"/>
      <geometry>
        <mesh filename="package://lr1_description/meshes/waist_L.STL"/>
      </geometry>
    </collision>
  </link>
  <joint name="bumblebee2_joint" type="fixed">
    <origin rpy="0 0 0" xyz="-0.05082 0 0.522"/>
    <parent link="waist_link"/>
    <child link="bumblebee2_link"/>
  </joint>
  <link name="bumblebee2_link">
    <visual>
      <geometry>
        <mesh filename="package://lr1_description/meshes/bumblebee2.STL"/>
      </geometry>
      <material name="byellow">
        <color rgba="1 0.67 0 1"/>
      </material>
    </visual>
  </link>
  <link name="left_camera_frame"/>
  <joint name="left_camera_frame_joint" type="fixed">
    <origin rpy="-1.5707963265 0 -1.5707963265" xyz="0 0.06 0.0175"/>
    <parent link="bumblebee2_link"/>
    <child link="left_camera_frame"/>
  </joint>
  <link name="right_camera_frame"/>
  <joint name="right_camera_frame_joint" type="fixed">
    <origin rpy="-1.5707963265 0 -1.5707963265" xyz="0 -0.06 0.0175"/>
    <parent link="bumblebee2_link"/>
    <child link="right_camera_frame"/>
  </joint>
  <base/>
  <joint name="waist_left_lift_joint" type="prismatic">
    <axis xyz="0 0 1"/>
    <origin rpy="0 0 0.785375" xyz="0.02782 0.19982 0.126"/>
    <limit effort="1000.0" lower="0" upper="0.3" velocity="0.5"/>
    <parent link="waist_link"/>
    <child link="left_lift_link"/>
  </joint>
  <link name="left_lift_link">
    <visual>
      <geometry>
        <mesh filename="package://lr1_description/meshes/lift.STL"/>
      </geometry>
      <material name="blue">
        <color rgba="0 0.67 1 1"/>
      </material>
    </visual>
    <collision>
      <origin rpy="0 0 0" xyz="0 0 -0.01"/>
      <geometry>
        <cylinder length="0.02" radius="0.043"/>
      </geometry>
    </collision>
  </link>
  <joint name="left_lift_upperarm_joint" type="revolute">
    <axis xyz="0 0 1"/>
    <origin rpy="0 0 0" xyz="0 0 0.0015"/>
    <limit effort="1000.0" lower="-1.57075" upper="1.57075" velocity="0.5"/>
    <parent link="left_lift_link"/>
    <child link="left_upperarm_link"/>
  </joint>
  <link name="left_upperarm_link">
    <visual>
      <geometry>
        <mesh filename="package://lr1_description/meshes/upperarm.STL"/>
      </geometry>
      <material name="green">
        <color rgba="0.33 0.67 0.5 1"/>
      </material>
    </visual>
    <collision>
      <geometry>
        <mesh filename="package://lr1_description/meshes/upperarm_L.STL"/>
      </geometry>
    </collision>
  </link>
  <joint name="left_upperarm_forearm_joint" type="revolute">
    <axis xyz="0 0 1"/>
    <origin rpy="0 0 0" xyz="0.33 0 0.0245"/>
    <limit effort="1000.0" lower="-2.35619448975" upper="0.0" velocity="0.5"/>
    <parent link="left_upperarm_link"/>
    <child link="left_forearm_link"/>
  </joint>
  <link name="left_forearm_link">
    <visual>
      <geometry>
        <mesh filename="package://lr1_description/meshes/forearm.STL"/>
      </geometry>
      <material name="orange">
        <color rgba="1 0.67 0.5 1"/>
      </material>
    </visual>
    <collision>
      <geometry>
        <mesh filename="package://lr1_description/meshes/forearm_L.STL"/>
      </geometry>
    </collision>
  </link>
  <link name="left_arm_end_frame"/>
  <joint name="left_arm_end_frame_joint" type="fixed">
    <origin rpy="0 0 0" xyz="0.25 0 0.0125"/>
    <parent link="left_forearm_link"/>
    <child link="left_arm_end_frame"/>
  </joint>
  <joint name="waist_right_lift_joint" type="prismatic">
    <axis xyz="0 0 1"/>
    <origin rpy="0 0 -0.785375" xyz="0.02782 -0.19982 0.126"/>
    <limit effort="1000.0" lower="0" upper="0.3" velocity="0.5"/>
    <parent link="waist_link"/>
    <child link="right_lift_link"/>
  </joint>
  <link name="right_lift_link">
    <visual>
      <geometry>
        <mesh filename="package://lr1_description/meshes/lift.STL"/>
      </geometry>
      <material name="blue">
        <color rgba="0 0.67 1 1"/>
      </material>
    </visual>
    <collision>
      <origin rpy="0 0 0" xyz="0 0 -0.01"/>
      <geometry>
        <cylinder length="0.02" radius="0.043"/>
      </geometry>
    </collision>
  </link>
  <joint name="right_lift_upperarm_joint" type="revolute">
    <axis xyz="0 0 1"/>
    <origin rpy="0 0 0" xyz="0 0 0.0015"/>
    <limit effort="1000.0" lower="-1.57075" upper="1.57075" velocity="0.5"/>
    <parent link="right_lift_link"/>
    <child link="right_upperarm_link"/>
  </joint>
  <link name="right_upperarm_link">
    <visual>
      <geometry>
        <mesh filename="package://lr1_description/meshes/upperarm.STL"/>
      </geometry>
      <material name="green">
        <color rgba="0.33 0.67 0.5 1"/>
      </material>
    </visual>
    <collision>
      <geometry>
        <mesh filename="package://lr1_description/meshes/upperarm_L.STL"/>
      </geometry>
    </collision>
  </link>
  <joint name="right_upperarm_forearm_joint" type="revolute">
    <axis xyz="0 0 1"/>
    <origin rpy="0 0 0" xyz="0.33 0 0.0245"/>
    <limit effort="1000.0" lower="0.0" upper="2.35619448975" velocity="0.5"/>
    <parent link="right_upperarm_link"/>
    <child link="right_forearm_link"/>
  </joint>
  <link name="right_forearm_link">
    <visual>
      <geometry>
        <mesh filename="package://lr1_description/meshes/forearm.STL"/>
      </geometry>
      <material name="orange">
        <color rgba="1 0.67 0.5 1"/>
      </material>
    </visual>
    <collision>
      <geometry>
        <mesh filename="package://lr1_description/meshes/forearm_L.STL"/>
      </geometry>
    </collision>
  </link>
  <link name="right_arm_end_frame"/>
  <joint name="right_arm_end_frame_joint" type="fixed">
    <origin rpy="0 0 0" xyz="0.25 0 0.0125"/>
    <parent link="right_forearm_link"/>
    <child link="right_arm_end_frame"/>
  </joint>
  <joint name="arm_wrist_joint" type="revolute">
    <axis xyz="1 0 0"/>
    <origin rpy="0 0 0" xyz="0.25 0 0.0125"/>
    <limit effort="1000.0" lower="-1.5707963265" upper="1.5707963265" velocity="0.5"/>
    <parent link="right_forearm_link"/>
    <child link="sawwrist_link"/>
  </joint>
  <link name="sawwrist_link">
    <visual>
      <geometry>
        <mesh filename="package://lr1_description/meshes/saw_wrist.STL"/>
      </geometry>
      <material name="blue">
        <color rgba="0 0.67 1 1"/>
      </material>
    </visual>
    <collision>
      <origin rpy="0 1.5707963265 0" xyz="0.078 0 0"/>
      <geometry>
        <cylinder length="0.156" radius="0.045"/>
      </geometry>
    </collision>
  </link>
  <joint name="saw_joint" type="revolute">
    <axis xyz="0 1 0"/>
    <origin rpy="0 0 0" xyz="0.134 0 0"/>
    <limit effort="1000.0" lower="-1.5707963265" upper="1.5707963265" velocity="0.5"/>
    <parent link="sawwrist_link"/>
    <child link="saw_link"/>
  </joint>
  <link name="saw_link">
    <visual>
      <origin xyz="0.035 0 -0.0004"/>
      <geometry>
        <mesh filename="package://lr1_description/meshes/saw.STL"/>
      </geometry>
      <material name="blue2">
        <color rgba="0 0.33 1 1"/>
      </material>
    </visual>
    <collision>
      <origin rpy="0 0 0" xyz="0.006 0 0.0066"/>
      <geometry>
        <box size="0.078 0.07 0.062"/>
      </geometry>
    </collision>
  </link>
  <bumblebee2/>
</robot>

