<?xml version="1.0"?>

<robot name="saw" xmlns:xacro="http://ros.org/wiki/xacro">

  <property name="PI" value="3.141592653" />
  <macro name="saw">
    <joint name="arm_wrist_joint" type="revolute">
      <axis xyz="1 0 0"/>
      <origin xyz="0.25 0 0.0125" rpy="0 0 0"/>
      <limit lower="${-PI/2}" upper="${PI/2}" velocity="0.5" effort="1000.0"/>
      <parent link="right_forearm_link"/>
      <child link="sawwrist_link"/>
    </joint>

    <link name="sawwrist_link">
      <visual>
        <geometry>
          <mesh filename="package://lr1_description/meshes/saw_wrist.STL" />
        </geometry>
        <material name="blue">
          <color rgba="0 0.67 1 1"/>
        </material>
      </visual>
      <collision>
        <origin rpy="0 ${PI/2} 0" xyz="0.078 0 0"  />
        <geometry>
          <cylinder length="0.156" radius="0.045"/>
        </geometry>
      </collision>
    </link>

    <joint name="saw_joint" type="revolute">
      <axis xyz="0 1 0"/>
      <origin xyz="0.134 0 0" rpy="0 0 0"/>
      <limit lower="${-PI/2}" upper="${PI/2}" velocity="0.5" effort="1000.0"/>
      <parent link="sawwrist_link"/>
      <child link="saw_link"/>
    </joint>

    <link name="saw_link">
      <visual>
        <origin xyz="0.035 0 -0.0004" />
        <geometry>
          <mesh filename="package://lr1_description/meshes/saw.STL" />
        </geometry>
        <material name="blue2">
          <color rgba="0 0.33 1 1"/>
        </material>
      </visual>
      <collision>
        <origin rpy="0 0 0" xyz="${-0.029+0.035} 0 ${0.007-0.0004}"  />
        <geometry>
          <box size="0.078 0.07 0.062"/>
        </geometry>
      </collision>
    </link>

  </macro>
</robot>
